<?xml version="1.0"?>
<robot xmlns:xacro="http://www.ros.org/wiki/xacro" name ="argo_drive_robot">

    <xacro:include filename="$(find ros2_ws_robot_launch)/config/inertial_macros.xacro"/>

    <!-- Materialien -->
    <material name="grey">
        <color rgba="0.7 0.7 0.7 1"/>
    </material>

    <material name="green">
        <color rgba="0 1 0 1"/>
    </material>

    <material name="white">
        <color rgba="1 1 1 1"/>
    </material>

    <material name="blue">
        <color rgba="0 0 1 1"/>
    </material>

    <material name="red">
        <color rgba="1 0 0 1"/>
    </material>

    <link name="base_link"/>

    
    <joint name="base_footprint_joint" type="fixed">
        <parent link="base_link"/>
        <child link="base_footprint"/>
        <origin xyz= "0 0 0" rpy= "0 0 0 "/>
    </joint>

    <link name= "base_footprint">
        <geometry>
                <box size="0.6 1 0.05" />
        </geometry>
    </link>
    

    <!-- Grundplatte des Roboters -->
    <joint name="robot_base_joint" type="fixed">
        <parent link="base_link" />
        <child link="robot_base" />
        <origin xyz="0 0 0.125" rpy="0 0 0" />
    </joint>

    <link name="robot_base">
        <visual>
            <geometry>
                <box size="0.6 1 0.05" />
            </geometry>
            <material name="grey"/>
        </visual>
        
        <collision>
            <geometry>
                <box size="0.6 1 0.05" />
            </geometry>
            
        </collision>
        <xacro:inertial_box mass="2" x="0.6" y="1" z="0.5">
            <origin xyz="0 0 0" rpy="0 0 0"/>
        </xacro:inertial_box>
    </link>

    <!-- Scannermitte -->
    <joint name="scan_middle" type="fixed">
        <parent link="base_link" />
        <child link="scan_middle_link" />
        <origin xyz="0.3 0 0.2" rpy="0 0 0" />
    </joint>

    <link name="scan_middle_link">
    </link>


    <joint name="scan_middle_scan_joint" type="fixed">
        <parent link="scan_middle_link" />
        <child link="scan_middle_scan" />
        <origin xyz="0 0 0" rpy="0 0 -1.5708" />
    </joint>


    <link name="scan_middle_scan">
    </link>



    <joint name="scan1_joint" type="fixed">
        <parent link="scan_middle_link" />
        <child link="scan1" />
        <origin xyz="0 0.5  0" rpy="0 0 ${pi/2}" />
    </joint>

    <link name="scan1">
        
        <visual>
            <geometry>
                <cylinder radius="0.05" length="0.1" />
            </geometry>
            <origin xyz="0 0 0" rpy="0 0 ${pi/2}" />
            <material name="white"/>
        </visual>
        
        <collision>
            <geometry>
                    <cylinder radius="0.05" length="0.1" />
            </geometry>
            
        </collision>
        <xacro:inertial_cylinder mass="0.1" length="0.1" radius="0.05">
             <origin xyz="0 0 0" rpy="0 0 1.57075" />
        </xacro:inertial_cylinder>
        

    </link>
    
    <gazebo reference="scan1">
        <sensor type="gpu_lidar" name="laser1">
            <pose> 0 0 0 0 0 0 </pose>
            <visualize> false </visualize>
            <update_rate>30</update_rate>
            <lidar>
                 <scan>
                    <horizontal>
                        <samples>360</samples>
                        <resolution>1.0</resolution>
                        <min_angle> -2.399827 </min_angle>
                        <max_angle> 2.399827 </max_angle>
                    </horizontal>
                </scan>
                <range>
                    <min>0.3</min>
                    <max>12.0</max>
                    <resolution>0.01</resolution>
                </range>
            </lidar>
            <topic> scan1 </topic>
            <gz_frame_id>scan1</gz_frame_id>
        </sensor>
    </gazebo>
    

  

    <!-- Scanner 2  -->
    <joint name="scan2_joint" type="fixed">
        <parent link="scan_middle_link" />
        <child link="scan2" />
        <origin xyz="0 -0.5 0" rpy="0 0 ${pi*1.5}" />
    </joint>

    <link name="scan2">
        
        <visual>
            <geometry>
                <cylinder radius="0.05" length="0.1" />
            </geometry>
            <origin xyz="0 0 0 " rpy="0 0 ${pi*1.5}" /> 
            <material name="white"/>
        </visual>
        <collision>
             <geometry>
                <cylinder radius="0.05" length="0.1" />
            </geometry>
            
        </collision>
        <xacro:inertial_cylinder mass="0.1" length="0.1" radius="0.05">
            <origin xyz="0 0 0" rpy="0 0 0"/>
        </xacro:inertial_cylinder>
        
    </link>
    
    
    <gazebo reference="scan2">
        <sensor type="gpu_lidar" name="laser2">
            <pose> 0 0 0 0 0 0 </pose>
            <visualize> false </visualize>
            <update_rate>30</update_rate>
            <lidar>
                 <scan>
                    <horizontal>
                        <samples>360</samples>
                        <resolution>1.0</resolution>
                        <min_angle> -2.399827 </min_angle>
                        <max_angle> 2.399827 </max_angle>
                    </horizontal>
                </scan>
                <range>
                    <min>0.3</min>
                    <max>12.0</max>
                    <resolution>0.01</resolution>
                </range>
            </lidar>
            <topic> scan2 </topic>
            <gz_frame_id>scan2</gz_frame_id>
        </sensor>
    </gazebo>
    

      
    

    <!-- Verbindung für Lenken (Drehen um Z-Achse) -->
    <joint name="steering_joint" type="continuous">
        <parent link="base_link"/>
        <child link="rear_mount"/>
        <origin xyz="-0.37 0 0.0625" rpy="0 0 0"/> <!-- Position des Halters -->
        <axis xyz="0 0 -1"/> <!-- Rotation um Z-Achse für Lenken -->
    </joint>
    
   


    <!-- Hinterrad-Halterung -->
    <link name="rear_mount">
        <visual>
            <geometry>
                <box size="0.05 0.05 0.05"/> <!-- Kleine Verbindungshalterung -->
            </geometry>
            <origin xyz="0 0 0" rpy="0 0 0"/>
            <material name="blue"/>
        </visual>
        <xacro:inertial_box mass="0.01" x="0.001" y="0.001" z="0.001">
            <origin xyz="0 0 0" rpy="0 0 0"/>
        </xacro:inertial_box>
        

    </link>

     <!-- Verbindung für Antrieb (Drehen um X-Achse) -->
    <joint name="traction_joint" type="continuous">
        <parent link="rear_mount"/> <!-- Antriebsbewegung auf der Halterung -->
        <child link="rear_drive_wheel"/>
        <origin xyz="0 0 0" rpy="0 0 0"/>
        <axis xyz="0 1 0"/> <!-- Rotation um X-Achse für Antrieb -->
    </joint>

    <!-- Hinterrad -->
    <link name="rear_drive_wheel">
        <visual>
            <geometry>
                <cylinder radius="0.0625" length="0.04"/>
            </geometry>
            <origin xyz="0 0 0" rpy="${pi/2} 0 0"/>
            <material name="blue"/>
        </visual>
        
        <collision>
           <geometry>
                <cylinder radius="0.0625" length="0.04"/>
            </geometry>
            <origin xyz="0 0 0" rpy="${pi/2} 0 0"/>
        </collision>
        
        <xacro:inertial_cylinder mass="0.5" length="0.04" radius="0.0625">
            <origin xyz="0 0 0" rpy="0 0 0"/>
        </xacro:inertial_cylinder>
    </link>



    

    <!-- Vordere linke feststehende Rad -->
    <joint name="left_wheel_joint" type="continuous">
        <parent link="base_link"/>
        <child link="front_left_wheel"/>
        <origin xyz="0.3 0.51 0.0625" rpy="${pi/2} 0 0"/>
        <axis xyz="0 0 1"/> <!-- Rotation um X-Achse für Antrieb -->
    </joint>
    
    <link name="front_left_wheel">
        <visual>
            <geometry>
                <cylinder radius="0.0625" length="0.02"/>
            </geometry>
            <material name="green"/>
        </visual>
        <collision>
            <geometry>
                    <cylinder radius="0.0625" length="0.02"/>
            </geometry>   
        </collision>
        <xacro:inertial_cylinder mass="0.5" length="0.02" radius="0.0625">
            <origin xyz="0 0 0" rpy="0 0 0"/>
        </xacro:inertial_cylinder>

     
    </link>

    

    <!-- Vordere rechte feststehende Rad -->
     <joint name="right_wheel_joint" type="continuous">
        <parent link="base_link"/>
        <child link="front_right_wheel"/>
        <origin xyz="0.3 -0.51 0.0625" rpy="${pi/2} 0 0"/>
        <axis xyz="0 0 1"/> <!-- Rotation um X-Achse für Antrieb -->
    </joint>

    <link name="front_right_wheel">
        <visual>
            <geometry>
                <cylinder radius="0.0625" length="0.02"/>
            </geometry>
            
            <material name="red"/>
        </visual>
        <collision>
            <geometry>
                    <cylinder radius="0.0625" length="0.02"/>
            </geometry>
        </collision>
        <xacro:inertial_cylinder mass="0.5" length="0.02" radius="0.0625">
            <origin xyz="0 0 0" rpy="0 0 0"/>
        </xacro:inertial_cylinder>

    </link>
    <!--
    <transmission name="front_wheel_transmission">
        <type>transmission_interface/SimpleTransmission</type>
        <joint name="traction_joint">
            <hardwareInterface>hardware_interface/VelocityJointInterface</hardwareInterface>
        </joint>
        <actuator name="front_wheel_motor">
            <mechanicalReduction>1</mechanicalReduction>
        </actuator>
        </transmission>

        <transmission name="steering_transmission">
        <type>transmission_interface/SimpleTransmission</type>
        <joint name="steering_joint">
            <hardwareInterface>hardware_interface/PositionJointInterface</hardwareInterface>
        </joint>
        <actuator name="steering_motor">
            <mechanicalReduction>1</mechanicalReduction>
        </actuator>
    </transmission>
    -->


    <ros2_control name="IgnitionSystem" type="system">
        <hardware>
            <plugin>ign_ros2_control/IgnitionSystem</plugin>
        </hardware>

        <joint name="steering_joint">
            <command_interface name="position"/>
            <state_interface name="position"/>
        </joint>
        <joint name="traction_joint">
            <command_interface name="velocity"/>
            <state_interface name="position"/>
            <state_interface name="velocity"/>
        </joint>
    </ros2_control>
    
     <gazebo>
    <plugin filename="ign_ros2_control-system" name="ign_ros2_control::IgnitionROS2ControlPlugin">
      <parameters>$(find ros2_ws_robot_launch)/params/tricycle_drive_controller.yaml</parameters>
    </plugin>
  </gazebo>
    
</robot>

